<?xml version='1.0' encoding='utf-8'?>
<robot xmlns:xacro="http://www.ros.org/wiki/xacro" name="otto">
   <xacro:include filename="$(find otto)/urdf/materials.xacro" />
   <link name="dummy_link" />
   <joint name="dummy_link_joint" type="fixed">
      <parent link="dummy_link" />
      <child link="base_link:1" />
   </joint>
   <link name="base_link_1">
      <inertial>
         <origin xyz="-0.017480908878091606 0.03519882134873651 -0.025083002755304264" rpy="0.0 0.0 0.0" />
         <mass value="0.03208248801839897" />
         <inertia ixx="2.49503e-05" iyy="2.55347e-05" izz="4.0534700000000003e-05" ixy="1.7290000000000002e-07" iyz="7.21e-08" ixz="-2.4710000000000004e-07" />
      </inertial>
      <visual>
         <origin xyz="0.0 0.0 -0.09000000000000001" rpy="0.0 0.0 0.0" />
         <geometry>
            <mesh filename="package://otto/meshes/base_link_1.stl" scale="0.001 0.001 0.001" />
         </geometry>
         <material name="ABS{Branco}" />
      </visual>
      <collision>
         <origin xyz="0.0 0.0 -0.09000000000000001" rpy="0.0 0.0 0.0" />
         <geometry>
            <mesh filename="package://otto/meshes/base_link_1.stl" scale="0.001 0.001 0.001" />
         </geometry>
      </collision>
   </link>
   <link name="RightLeg_1">
      <inertial>
         <origin xyz="-1.0223024729112406e-05 0.0 -0.01867704290601307" rpy="0.0 0.0 0.0" />
         <mass value="0.008348175211097226" />
         <inertia ixx="1.7007e-06" iyy="2.6586e-06" izz="1.5726e-06" ixy="-0.0" iyz="-0.0" ixz="1.2080000000000002e-07" />
      </inertial>
      <visual>
         <origin xyz="0.012391174437753782 -0.005158205912836666 -0.051000000000000004" rpy="0.0 0.0 0.0" />
         <geometry>
            <mesh filename="package://otto/meshes/RightLeg_1.stl" scale="0.001 0.001 0.001" />
         </geometry>
         <material name="ABS{Branco}" />
      </visual>
      <collision>
         <origin xyz="0.012391174437753782 -0.005158205912836666 -0.051000000000000004" rpy="0.0 0.0 0.0" />
         <geometry>
            <mesh filename="package://otto/meshes/RightLeg_1.stl" scale="0.001 0.001 0.001" />
         </geometry>
      </collision>
   </link>
   <link name="LeftLeg_1">
      <inertial>
         <origin xyz="8.637669678136283e-05 0.0 -0.018540132277720875" rpy="0.0 0.0 0.0" />
         <mass value="0.008295768110971862" />
         <inertia ixx="1.6731e-06" iyy="2.6214e-06" izz="1.5575000000000001e-06" ixy="0.0" iyz="0.0" ixz="1.383e-07" />
      </inertial>
      <visual>
         <origin xyz="0.016999572875253794 -0.0610004271247462 -0.053000000000000005" rpy="0.0 0.0 0.0" />
         <geometry>
            <mesh filename="package://otto/meshes/LeftLeg_1.stl" scale="0.001 0.001 0.001" />
         </geometry>
         <material name="ABS{Branco}" />
      </visual>
      <collision>
         <origin xyz="0.016999572875253794 -0.0610004271247462 -0.053000000000000005" rpy="0.0 0.0 0.0" />
         <geometry>
            <mesh filename="package://otto/meshes/LeftLeg_1.stl" scale="0.001 0.001 0.001" />
         </geometry>
      </collision>
   </link>
   <link name="Ultrasonic_Sensor_v1_1_1">
      <inertial>
         <origin xyz="0.015667100965246424 0.035094427086301554 0.015158230340085038" rpy="0.0 0.0 0.0" />
         <mass value="0.044351271100452234" />
         <inertia ixx="9.202000000000001e-06" iyy="1.6735000000000002e-06" izz="8.9476e-06" ixy="-0.0" iyz="1.21e-08" ixz="-9.1e-09" />
      </inertial>
      <visual>
         <origin xyz="0.0 0.0 -0.09000000000000001" rpy="0.0 0.0 0.0" />
         <geometry>
            <mesh filename="package://otto/meshes/Ultrasonic_Sensor_v1_1_1__Corpo1.stl" scale="0.001 0.001 0.001" />
         </geometry>
         <material name="Opaque{20,22,159}" />
      </visual>
      <visual>
         <origin xyz="0.0 0.0 -0.09000000000000001" rpy="0.0 0.0 0.0" />
         <geometry>
            <mesh filename="package://otto/meshes/Ultrasonic_Sensor_v1_1_1__Corpo2.stl" scale="0.001 0.001 0.001" />
         </geometry>
         <material name="Alumínio_Polido" />
      </visual>
      <visual>
         <origin xyz="0.0 0.0 -0.09000000000000001" rpy="0.0 0.0 0.0" />
         <geometry>
            <mesh filename="package://otto/meshes/Ultrasonic_Sensor_v1_1_1__Corpo3.stl" scale="0.001 0.001 0.001" />
         </geometry>
         <material name="Alumínio_Polido" />
      </visual>
      <visual>
         <origin xyz="0.0 0.0 -0.09000000000000001" rpy="0.0 0.0 0.0" />
         <geometry>
            <mesh filename="package://otto/meshes/Ultrasonic_Sensor_v1_1_1__Corpo4.stl" scale="0.001 0.001 0.001" />
         </geometry>
         <material name="Aço_Acetinado" />
      </visual>
      <visual>
         <origin xyz="0.0 0.0 -0.09000000000000001" rpy="0.0 0.0 0.0" />
         <geometry>
            <mesh filename="package://otto/meshes/Ultrasonic_Sensor_v1_1_1__Corpo5.stl" scale="0.001 0.001 0.001" />
         </geometry>
         <material name="Alumínio_Anodizadobruto{Cinza}" />
      </visual>
      <visual>
         <origin xyz="0.0 0.0 -0.09000000000000001" rpy="0.0 0.0 0.0" />
         <geometry>
            <mesh filename="package://otto/meshes/Ultrasonic_Sensor_v1_1_1__Corpo6.stl" scale="0.001 0.001 0.001" />
         </geometry>
         <material name="Aço_Acetinado" />
      </visual>
      <visual>
         <origin xyz="0.0 0.0 -0.09000000000000001" rpy="0.0 0.0 0.0" />
         <geometry>
            <mesh filename="package://otto/meshes/Ultrasonic_Sensor_v1_1_1__Corpo7.stl" scale="0.001 0.001 0.001" />
         </geometry>
         <material name="Aço_Acetinado" />
      </visual>
      <visual>
         <origin xyz="0.0 0.0 -0.09000000000000001" rpy="0.0 0.0 0.0" />
         <geometry>
            <mesh filename="package://otto/meshes/Ultrasonic_Sensor_v1_1_1__Corpo8.stl" scale="0.001 0.001 0.001" />
         </geometry>
         <material name="Aço_Acetinado" />
      </visual>
      <visual>
         <origin xyz="0.0 0.0 -0.09000000000000001" rpy="0.0 0.0 0.0" />
         <geometry>
            <mesh filename="package://otto/meshes/Ultrasonic_Sensor_v1_1_1__Corpo9.stl" scale="0.001 0.001 0.001" />
         </geometry>
         <material name="Alumínio_Anodizadobruto{Cinza}" />
      </visual>
      <visual>
         <origin xyz="0.0 0.0 -0.09000000000000001" rpy="0.0 0.0 0.0" />
         <geometry>
            <mesh filename="package://otto/meshes/Ultrasonic_Sensor_v1_1_1__Corpo10.stl" scale="0.001 0.001 0.001" />
         </geometry>
         <material name="Aço_Acetinado" />
      </visual>
      <visual>
         <origin xyz="0.0 0.0 -0.09000000000000001" rpy="0.0 0.0 0.0" />
         <geometry>
            <mesh filename="package://otto/meshes/Ultrasonic_Sensor_v1_1_1__Corpo11.stl" scale="0.001 0.001 0.001" />
         </geometry>
         <material name="Aço_Acetinado" />
      </visual>
      <visual>
         <origin xyz="0.0 0.0 -0.09000000000000001" rpy="0.0 0.0 0.0" />
         <geometry>
            <mesh filename="package://otto/meshes/Ultrasonic_Sensor_v1_1_1__Corpo12.stl" scale="0.001 0.001 0.001" />
         </geometry>
         <material name="Materialdebase–Transparente" />
      </visual>
      <visual>
         <origin xyz="0.0 0.0 -0.09000000000000001" rpy="0.0 0.0 0.0" />
         <geometry>
            <mesh filename="package://otto/meshes/Ultrasonic_Sensor_v1_1_1__Corpo13.stl" scale="0.001 0.001 0.001" />
         </geometry>
         <material name="Alumínio_Polido" />
      </visual>
      <visual>
         <origin xyz="0.0 0.0 -0.09000000000000001" rpy="0.0 0.0 0.0" />
         <geometry>
            <mesh filename="package://otto/meshes/Ultrasonic_Sensor_v1_1_1__Corpo14.stl" scale="0.001 0.001 0.001" />
         </geometry>
         <material name="Alumínio_Polido" />
      </visual>
      <collision>
         <origin xyz="0.0 0.0 -0.09000000000000001" rpy="0.0 0.0 0.0" />
         <geometry>
            <mesh filename="package://otto/meshes/Ultrasonic_Sensor_v1_1_1.stl" scale="0.001 0.001 0.001" />
         </geometry>
      </collision>
   </link>
   <link name="Head_1_1">
      <inertial>
         <origin xyz="-0.017855193601269966 0.03577461405901634 0.019109172286024715" rpy="0.0 0.0 0.0" />
         <mass value="0.024198404764366552" />
         <inertia ixx="1.64375e-05" iyy="1.5669500000000003e-05" izz="2.6288000000000003e-05" ixy="2.7180000000000004e-07" iyz="8.04e-08" ixz="9.079999999999999e-08" />
      </inertial>
      <visual>
         <origin xyz="-0.00011642897127503943 -6.011660760120062e-07 -0.08903341742506664" rpy="0.0 0.0 0.0" />
         <geometry>
            <mesh filename="package://otto/meshes/Head_1_1.stl" scale="0.001 0.001 0.001" />
         </geometry>
         <material name="Plástico_Fosco{Amarelo}" />
      </visual>
      <collision>
         <origin xyz="-0.00011642897127503943 -6.011660760120062e-07 -0.08903341742506664" rpy="0.0 0.0 0.0" />
         <geometry>
            <mesh filename="package://otto/meshes/Head_1_1.stl" scale="0.001 0.001 0.001" />
         </geometry>
      </collision>
   </link>
   <link name="FootRight_1">
      <inertial>
         <origin xyz="-0.01692768844509787 -0.0076979010066632785 -0.010195669876470142" rpy="0.0 0.0 0.0" />
         <mass value="0.012749332366692664" />
         <inertia ixx="2.4864e-06" iyy="5.3642e-06" izz="6.5881000000000005e-06" ixy="-7.58e-08" iyz="-4.0549999999999997e-07" ixz="-6.1e-08" />
      </inertial>
      <visual>
         <origin xyz="-0.005508825562246209 -0.005158205912836655 -0.02" rpy="0.0 0.0 0.0" />
         <geometry>
            <mesh filename="package://otto/meshes/FootRight_1.stl" scale="0.001 0.001 0.001" />
         </geometry>
         <material name="ABS{Branco}" />
      </visual>
      <collision>
         <origin xyz="-0.005508825562246209 -0.005158205912836655 -0.02" rpy="0.0 0.0 0.0" />
         <geometry>
            <mesh filename="package://otto/meshes/FootRight_1.stl" scale="0.001 0.001 0.001" />
         </geometry>
      </collision>
   </link>
   <link name="FootLeft_1">
      <inertial>
         <origin xyz="-0.016928050017156856 0.004599559866878043 -0.012894741270675017" rpy="0.0 0.0 0.0" />
         <mass value="0.012746842677145294" />
         <inertia ixx="2.4861000000000002e-06" iyy="5.3642e-06" izz="6.587899999999999e-06" ixy="7.58e-08" iyz="4.056e-07" ixz="-6.1e-08" />
      </inertial>
      <visual>
         <origin xyz="-0.0005004271247461972 -0.06100042712474619 -0.022000000000000002" rpy="0.0 0.0 0.0" />
         <geometry>
            <mesh filename="package://otto/meshes/FootLeft_1.stl" scale="0.001 0.001 0.001" />
         </geometry>
         <material name="ABS{Branco}" />
      </visual>
      <collision>
         <origin xyz="-0.0005004271247461972 -0.06100042712474619 -0.022000000000000002" rpy="0.0 0.0 0.0" />
         <geometry>
            <mesh filename="package://otto/meshes/FootLeft_1.stl" scale="0.001 0.001 0.001" />
         </geometry>
      </collision>
   </link>
   <joint name="Revolucionar46" type="revolute">
      <origin xyz="-0.012391174437753782 0.005158205912836682 -0.039" rpy="0.0 0.0 0.0" />
      <parent link="base_link_1" />
      <child link="RightLeg_1" />
      <axis xyz="0.0 0.0 1.0" />
      <limit upper="1.5707963267948966" lower="-1.5707963267948966" effort="100.0" velocity="100.0" />
   </joint>
   <joint name="Revolucionar47" type="revolute">
      <origin xyz="-0.016999572875253794 0.061000427124746216 -0.037000000000000005" rpy="0.0 0.0 0.0" />
      <parent link="base_link_1" />
      <child link="LeftLeg_1" />
      <axis xyz="0.0 0.0 -1.0" />
      <limit upper="1.5707963267948966" lower="-1.5707963267948966" effort="100.0" velocity="100.0" />
   </joint>
   <joint name="Gruporígido43" type="fixed">
      <origin xyz="0.0 0.0 0.0" rpy="0.0 0.0 0.0" />
      <parent link="base_link_1" />
      <child link="Ultrasonic_Sensor_v1_1_1" />
   </joint>
   <joint name="Gruporígido43_0" type="fixed">
      <origin xyz="0.00011642897127504436 6.011660760218973e-07 -0.0009665825749333657" rpy="0.0 0.0 0.0" />
      <parent link="base_link_1" />
      <child link="Head_1_1" />
   </joint>
   <joint name="Revolucionar45" type="revolute">
      <origin xyz="0.0179 0.0 -0.031" rpy="0.0 0.0 0.0" />
      <parent link="RightLeg_1" />
      <child link="FootRight_1" />
      <axis xyz="1.0 0.0 0.0" />
      <limit upper="1.5707963267948966" lower="-1.5707963267948966" effort="100.0" velocity="100.0" />
   </joint>
   <joint name="Revolucionar44" type="revolute">
      <origin xyz="0.0175 0.0 -0.031" rpy="0.0 0.0 0.0" />
      <parent link="LeftLeg_1" />
      <child link="FootLeft_1" />
      <axis xyz="1.0 0.0 0.0" />
      <limit upper="1.5707963267948966" lower="-1.5707963267948966" effort="100.0" velocity="100.0" />
   </joint>
</robot>
