<?xml version='1.0' encoding='utf-8'?>
<robot xmlns:xacro="http://www.ros.org/wiki/xacro" name="otto">
   <xacro:include filename="$(find otto)/urdf/materials.xacro" />

   <!-- ==================== LINKS ==================== -->

   <!--
      base_footprint: link raiz fictício posicionado no chao (z=0).
      Sem massa nem inercia — serve apenas como referência estável para o Gazebo.
      O base_link fica 0.08 m acima do chao (altura real do corpo do Otto).
   -->
   <link name="base_footprint" />

   <joint name="base_footprint_joint" type="fixed">
      <origin xyz="0.0 0.0 0.08" rpy="0.0 0.0 0.0" />
      <parent link="base_footprint" />
      <child link="base_link" />
   </joint>

   <!--
      MASSAS ESCALADAS PARA ESTABILIDADE NUMERICA DO GAZEBO
      ===================================================
      Fator aplicado por grupo (mantendo razoes relativas do CAD real):
        base_link, pernas, cabeca  -> x10
        pes (contato crítico)      -> x12
        ultrasonico               -> x5
      Total simulado: ~1.26 kg  (original CAD: ~143 g)
      Inercias escaladas pelo mesmo fator (I proporcional a m).
      Todos os tensores passam na condiçao de Sylvester (ixx < iyy+izz, etc).
   -->

   <link name="base_link">
      <inertial>
         <origin xyz="-0.017480908878091606 0.03519882134873651 -0.025083002755304264" rpy="0.0 0.0 0.0" />
         <!-- original: 0.03208 kg  ->  x10 = 0.3208 kg -->
         <mass value="0.3208" />
         <inertia ixx="2.49503e-04" iyy="2.55347e-04" izz="4.05347e-04"
                  ixy="1.7290e-06"  iyz="7.21e-07"    ixz="-2.471e-06" />
      </inertial>
      <visual>
         <origin xyz="0.0 0.0 -0.09000000000000001" rpy="0.0 0.0 0.0" />
         <geometry>
            <mesh filename="package://otto/meshes/base_link_1.stl" scale="0.001 0.001 0.001" />
         </geometry>
         <material name="ABS{Branco}" />
      </visual>
      <collision>
         <origin xyz="0.0 0.0 -0.09000000000000001" rpy="0.0 0.0 0.0" />
         <geometry>
            <mesh filename="package://otto/meshes/base_link_1.stl" scale="0.001 0.001 0.001" />
         </geometry>
      </collision>
   </link>

   <link name="RightLeg_1">
      <inertial>
         <origin xyz="-1.0223024729112406e-05 0.0 -0.01867704290601307" rpy="0.0 0.0 0.0" />
         <!-- original: 0.008348 kg  ->  x10 = 0.08348 kg -->
         <mass value="0.08348" />
         <inertia ixx="1.7007e-05" iyy="2.6586e-05" izz="1.5726e-05"
                  ixy="0.0"        iyz="0.0"         ixz="1.208e-06" />
      </inertial>
      <visual>
         <origin xyz="0.012391174437753782 -0.005158205912836666 -0.051000000000000004" rpy="0.0 0.0 0.0" />
         <geometry>
            <mesh filename="package://otto/meshes/RightLeg_1.stl" scale="0.001 0.001 0.001" />
         </geometry>
         <material name="ABS{Branco}" />
      </visual>
      <collision>
         <origin xyz="0.012391174437753782 -0.005158205912836666 -0.051000000000000004" rpy="0.0 0.0 0.0" />
         <geometry>
            <mesh filename="package://otto/meshes/RightLeg_1.stl" scale="0.001 0.001 0.001" />
         </geometry>
      </collision>
   </link>

   <link name="LeftLeg_1">
      <inertial>
         <origin xyz="8.637669678136283e-05 0.0 -0.018540132277720875" rpy="0.0 0.0 0.0" />
         <!-- original: 0.008296 kg  ->  x10 = 0.08296 kg -->
         <mass value="0.08296" />
         <inertia ixx="1.6731e-05" iyy="2.6214e-05" izz="1.5575e-05"
                  ixy="0.0"        iyz="0.0"         ixz="1.383e-06" />
      </inertial>
      <visual>
         <origin xyz="0.016999572875253794 -0.0610004271247462 -0.053000000000000005" rpy="0.0 0.0 0.0" />
         <geometry>
            <mesh filename="package://otto/meshes/LeftLeg_1.stl" scale="0.001 0.001 0.001" />
         </geometry>
         <material name="ABS{Branco}" />
      </visual>
      <collision>
         <origin xyz="0.016999572875253794 -0.0610004271247462 -0.053000000000000005" rpy="0.0 0.0 0.0" />
         <geometry>
            <mesh filename="package://otto/meshes/LeftLeg_1.stl" scale="0.001 0.001 0.001" />
         </geometry>
      </collision>
   </link>

   <link name="Ultrasonic_Sensor_v1_1_1">
      <inertial>
         <origin xyz="0.015667100965246424 0.035094427086301554 0.015158230340085038" rpy="0.0 0.0 0.0" />
         <!-- link fixo decorativo: massa minima para nao afetar COM -->
         <mass value="0.001" />
         <inertia ixx="1.0e-07" iyy="1.0e-07" izz="1.0e-07"
                  ixy="0.0"     iyz="0.0"      ixz="0.0" />
      </inertial>
      <visual>
         <origin xyz="0.0 0.0 -0.09000000000000001" rpy="0.0 0.0 0.0" />
         <geometry>
            <mesh filename="package://otto/meshes/Ultrasonic_Sensor_v1_1_1__Corpo1.stl" scale="0.001 0.001 0.001" />
         </geometry>
         <material name="Opaque{20,22,159}" />
      </visual>
      <visual>
         <origin xyz="0.0 0.0 -0.09000000000000001" rpy="0.0 0.0 0.0" />
         <geometry>
            <mesh filename="package://otto/meshes/Ultrasonic_Sensor_v1_1_1__Corpo2.stl" scale="0.001 0.001 0.001" />
         </geometry>
         <material name="Alumínio_Polido" />
      </visual>
      <visual>
         <origin xyz="0.0 0.0 -0.09000000000000001" rpy="0.0 0.0 0.0" />
         <geometry>
            <mesh filename="package://otto/meshes/Ultrasonic_Sensor_v1_1_1__Corpo3.stl" scale="0.001 0.001 0.001" />
         </geometry>
         <material name="Alumínio_Polido" />
      </visual>
      <visual>
         <origin xyz="0.0 0.0 -0.09000000000000001" rpy="0.0 0.0 0.0" />
         <geometry>
            <mesh filename="package://otto/meshes/Ultrasonic_Sensor_v1_1_1__Corpo4.stl" scale="0.001 0.001 0.001" />
         </geometry>
         <material name="Aço_Acetinado" />
      </visual>
      <visual>
         <origin xyz="0.0 0.0 -0.09000000000000001" rpy="0.0 0.0 0.0" />
         <geometry>
            <mesh filename="package://otto/meshes/Ultrasonic_Sensor_v1_1_1__Corpo5.stl" scale="0.001 0.001 0.001" />
         </geometry>
         <material name="Alumínio_Anodizadobruto{Cinza}" />
      </visual>
      <visual>
         <origin xyz="0.0 0.0 -0.09000000000000001" rpy="0.0 0.0 0.0" />
         <geometry>
            <mesh filename="package://otto/meshes/Ultrasonic_Sensor_v1_1_1__Corpo6.stl" scale="0.001 0.001 0.001" />
         </geometry>
         <material name="Aço_Acetinado" />
      </visual>
      <visual>
         <origin xyz="0.0 0.0 -0.09000000000000001" rpy="0.0 0.0 0.0" />
         <geometry>
            <mesh filename="package://otto/meshes/Ultrasonic_Sensor_v1_1_1__Corpo7.stl" scale="0.001 0.001 0.001" />
         </geometry>
         <material name="Aço_Acetinado" />
      </visual>
      <visual>
         <origin xyz="0.0 0.0 -0.09000000000000001" rpy="0.0 0.0 0.0" />
         <geometry>
            <mesh filename="package://otto/meshes/Ultrasonic_Sensor_v1_1_1__Corpo8.stl" scale="0.001 0.001 0.001" />
         </geometry>
         <material name="Aço_Acetinado" />
      </visual>
      <visual>
         <origin xyz="0.0 0.0 -0.09000000000000001" rpy="0.0 0.0 0.0" />
         <geometry>
            <mesh filename="package://otto/meshes/Ultrasonic_Sensor_v1_1_1__Corpo9.stl" scale="0.001 0.001 0.001" />
         </geometry>
         <material name="Alumínio_Anodizadobruto{Cinza}" />
      </visual>
      <visual>
         <origin xyz="0.0 0.0 -0.09000000000000001" rpy="0.0 0.0 0.0" />
         <geometry>
            <mesh filename="package://otto/meshes/Ultrasonic_Sensor_v1_1_1__Corpo10.stl" scale="0.001 0.001 0.001" />
         </geometry>
         <material name="Aço_Acetinado" />
      </visual>
      <visual>
         <origin xyz="0.0 0.0 -0.09000000000000001" rpy="0.0 0.0 0.0" />
         <geometry>
            <mesh filename="package://otto/meshes/Ultrasonic_Sensor_v1_1_1__Corpo11.stl" scale="0.001 0.001 0.001" />
         </geometry>
         <material name="Aço_Acetinado" />
      </visual>
      <visual>
         <origin xyz="0.0 0.0 -0.09000000000000001" rpy="0.0 0.0 0.0" />
         <geometry>
            <mesh filename="package://otto/meshes/Ultrasonic_Sensor_v1_1_1__Corpo12.stl" scale="0.001 0.001 0.001" />
         </geometry>
         <material name="Materialdebase-Transparente" />
      </visual>
      <visual>
         <origin xyz="0.0 0.0 -0.09000000000000001" rpy="0.0 0.0 0.0" />
         <geometry>
            <mesh filename="package://otto/meshes/Ultrasonic_Sensor_v1_1_1__Corpo13.stl" scale="0.001 0.001 0.001" />
         </geometry>
         <material name="Alumínio_Polido" />
      </visual>
      <visual>
         <origin xyz="0.0 0.0 -0.09000000000000001" rpy="0.0 0.0 0.0" />
         <geometry>
            <mesh filename="package://otto/meshes/Ultrasonic_Sensor_v1_1_1__Corpo14.stl" scale="0.001 0.001 0.001" />
         </geometry>
         <material name="Alumínio_Polido" />
      </visual>
      <collision>
         <origin xyz="0.0 0.0 -0.09000000000000001" rpy="0.0 0.0 0.0" />
         <geometry>
            <mesh filename="package://otto/meshes/Ultrasonic_Sensor_v1_1_1.stl" scale="0.001 0.001 0.001" />
         </geometry>
      </collision>
   </link>

   <link name="Head_1_1">
      <inertial>
         <origin xyz="-0.017855193601269966 0.03577461405901634 0.019109172286024715" rpy="0.0 0.0 0.0" />
         <!-- link fixo: massa simbólica -->
         <mass value="0.024" />
         <inertia ixx="1.64375e-05" iyy="1.56695e-05" izz="2.6288e-05"
                  ixy="2.718e-07"   iyz="8.04e-08"     ixz="9.08e-08" />
      </inertial>
      <visual>
         <origin xyz="-0.00011642897127503943 -6.011660760120062e-07 -0.08903341742506664" rpy="0.0 0.0 0.0" />
         <geometry>
            <mesh filename="package://otto/meshes/Head_1_1.stl" scale="0.001 0.001 0.001" />
         </geometry>
         <material name="Plástico_Fosco{Amarelo}" />
      </visual>
      <collision>
         <origin xyz="-0.00011642897127503943 -6.011660760120062e-07 -0.08903341742506664" rpy="0.0 0.0 0.0" />
         <geometry>
            <mesh filename="package://otto/meshes/Head_1_1.stl" scale="0.001 0.001 0.001" />
         </geometry>
      </collision>
   </link>

   <link name="FootRight_1">
      <inertial>
         <origin xyz="-0.01692768844509787 -0.0076979010066632785 -0.010195669876470142" rpy="0.0 0.0 0.0" />
         <!-- original: 0.012749 kg  ->  x12 = 0.15299 kg -->
         <mass value="0.15299" />
         <inertia ixx="2.9837e-05" iyy="6.4370e-05" izz="7.9057e-05"
                  ixy="-9.096e-07"  iyz="-4.866e-06"  ixz="-7.32e-07" />
      </inertial>
      <visual>
         <origin xyz="-0.005508825562246209 -0.005158205912836655 -0.0137" rpy="0.0 0.0 0.0" />
         <geometry>
            <mesh filename="package://otto/meshes/FootRight_1.stl" scale="0.001 0.001 0.001" />
         </geometry>
         <material name="ABS{Branco}" />
      </visual>
      <collision>
         <origin xyz="-0.005508825562246209 -0.005158205912836655 -0.0137" rpy="0.0 0.0 0.0" />
         <geometry>
            <mesh filename="package://otto/meshes/FootRight_1.stl" scale="0.001 0.001 0.001" />
         </geometry>
      </collision>
   </link>

   <link name="FootLeft_1">
      <inertial>
         <origin xyz="-0.016928050017156856 0.004599559866878043 -0.012894741270675017" rpy="0.0 0.0 0.0" />
         <!-- original: 0.012747 kg  ->  x12 = 0.15296 kg -->
         <mass value="0.15296" />
         <inertia ixx="2.9833e-05" iyy="6.4370e-05" izz="7.9055e-05"
                  ixy="9.096e-07"   iyz="4.867e-06"   ixz="-7.32e-07" />
      </inertial>
      <visual>
         <origin xyz="-0.0005004271247461972 -0.06100042712474619 -0.0150" rpy="0.0 0.0 0.0" />
         <geometry>
            <mesh filename="package://otto/meshes/FootLeft_1.stl" scale="0.001 0.001 0.001" />
         </geometry>
         <material name="ABS{Branco}" />
      </visual>
      <collision>
         <origin xyz="-0.0005004271247461972 -0.06100042712474619 -0.0150" rpy="0.0 0.0 0.0" />
         <geometry>
            <mesh filename="package://otto/meshes/FootLeft_1.stl" scale="0.001 0.001 0.001" />
         </geometry>
      </collision>
   </link>

   <!-- ==================== JOINTS ==================== -->

   <joint name="leg_right_joint" type="revolute">
      <origin xyz="-0.012391174437753782 0.005158205912836682 -0.039" rpy="0.0 0.0 0.0" />
      <parent link="base_link" />
      <child link="RightLeg_1" />
      <axis xyz="0.0 0.0 1.0" />
      <limit upper="1.5707963267948966" lower="-1.5707963267948966" effort="100.0" velocity="100.0" />
   </joint>

   <joint name="leg_left_joint" type="revolute">
      <origin xyz="-0.016999572875253794 0.061000427124746216 -0.037000000000000005" rpy="0.0 0.0 0.0" />
      <parent link="base_link" />
      <child link="LeftLeg_1" />
      <axis xyz="0.0 0.0 -1.0" />
      <limit upper="1.5707963267948966" lower="-1.5707963267948966" effort="100.0" velocity="100.0" />
   </joint>

   <joint name="ultrasonic_joint" type="fixed">
      <origin xyz="0.0 0.0 0.0" rpy="0.0 0.0 0.0" />
      <parent link="base_link" />
      <child link="Ultrasonic_Sensor_v1_1_1" />
   </joint>

   <joint name="head_joint" type="fixed">
      <origin xyz="0.00011642897127504436 6.011660760218973e-07 -0.0009665825749333657" rpy="0.0 0.0 0.0" />
      <parent link="base_link" />
      <child link="Head_1_1" />
   </joint>

   <joint name="foot_right_joint" type="revolute">
      <origin xyz="0.0179 0.0 -0.031" rpy="0.0 0.0 0.0" />
      <parent link="RightLeg_1" />
      <child link="FootRight_1" />
      <axis xyz="1.0 0.0 0.0" />
      <limit upper="1.5707963267948966" lower="-1.5707963267948966" effort="100.0" velocity="100.0" />
   </joint>

   <joint name="foot_left_joint" type="revolute">
      <origin xyz="0.0175 0.0 -0.031" rpy="0.0 0.0 0.0" />
      <parent link="LeftLeg_1" />
      <child link="FootLeft_1" />
      <axis xyz="1.0 0.0 0.0" />
      <limit upper="1.5707963267948966" lower="-1.5707963267948966" effort="100.0" velocity="100.0" />
   </joint>

   <!-- ==================== GAZEBO PLUGINS ==================== -->
   <!--
      PID ajustado para massas x10:
        P: subiu de 1 -> 10  (torque proporcional à massa)
        D: subiu de 1 -> 0.5 (amortecimento — menor que P para nao oscilar)
        I: mantido em 0 (evita windup em juntas de baixa fricçao)
      Ponto de partida conservador; ajuste fino experimental:
        se oscilar -> reduza P para 7-8
        se lento/mole -> aumente P para 12-15
        se trepida -> aumente D para 0.8-1.0
   -->
   <gazebo>
      <plugin filename="gz-sim-joint-position-controller-system"
               name="gz::sim::systems::JointPositionController">
         <joint_name>leg_right_joint</joint_name>
         <topic>/leg_right_joint/cmd</topic>
         <p_gain>10.0</p_gain>
         <i_gain>0.0</i_gain>
         <d_gain>0.5</d_gain>
      </plugin>
      <plugin filename="gz-sim-joint-position-controller-system"
               name="gz::sim::systems::JointPositionController">
         <joint_name>leg_left_joint</joint_name>
         <topic>/leg_left_joint/cmd</topic>
         <p_gain>10.0</p_gain>
         <i_gain>0.0</i_gain>
         <d_gain>0.5</d_gain>
      </plugin>
      <plugin filename="gz-sim-joint-position-controller-system"
               name="gz::sim::systems::JointPositionController">
         <joint_name>foot_right_joint</joint_name>
         <topic>/foot_right_joint/cmd</topic>
         <p_gain>10.0</p_gain>
         <i_gain>0.0</i_gain>
         <d_gain>0.5</d_gain>
      </plugin>
      <plugin filename="gz-sim-joint-position-controller-system"
               name="gz::sim::systems::JointPositionController">
         <joint_name>foot_left_joint</joint_name>
         <topic>/foot_left_joint/cmd</topic>
         <p_gain>10.0</p_gain>
         <i_gain>0.0</i_gain>
         <d_gain>0.5</d_gain>
      </plugin>
   </gazebo>

   <!-- ==================== CONTATO/FRICTION PES ==================== -->
   <gazebo reference="FootRight_1">
      <surface>
         <friction>
            <ode>
               <mu>0.8</mu>
               <mu2>0.8</mu2>
            </ode>
         </friction>
         <contact>
            <ode>
               <kp>1e5</kp>
               <kd>1.0</kd>
               <min_depth>0.001</min_depth>
            </ode>
         </contact>
      </surface>
   </gazebo>

   <gazebo reference="FootLeft_1">
      <surface>
         <friction>
            <ode>
               <mu>0.8</mu>
               <mu2>0.8</mu2>
            </ode>
         </friction>
         <contact>
            <ode>
               <kp>1e5</kp>
               <kd>1.0</kd>
               <min_depth>0.001</min_depth>
            </ode>
         </contact>
      </surface>
   </gazebo>
   

</robot>
